Workbook

Sheet 2023 Tier 1
A1: Firm Name | B1: Retail Revenue | C1: Rest. Revenue | D1: Multifamily Revenue | E1: Industrial Revenue | F1: Data Center Revenue | G1: Hospitality Revenue | H1: Total Relevant Revenue | I1: LI Employees | J1: Data Source | K1: C1 Name | L1: C1 Title | M1: C1 Email | N1: C1 Phone | O1: C1 Office Address | P1: C2 Name | Q1: C2 Title | R1: C2 Email | S1: C2 Phone | T1: C2 Office Address | U1: C3 Name | V1: C3 Title | W1: C3 Email | X1: C3 Phone | Y1: C3 Office Address | Z1: C4 Name | AA1: C4 Title | AB1: C4 Email | AC1: C4 Phone | AD1: C4 Office Address | AE1: C5 Name | AF1: C5 Title | AG1: C5 Email | AH1: C5 Phone | AI1: C5 Office Address
A2: NORR | B2: 43068568 | C2: 11903850 | D2: 28972291 | E2: 8954881 | G2: 4226719 | H2: 97126309 | I2: 875 | J2: BDC 2023 | K2: Jonathan Hughes | L2: Chief Operating Officer | M2: jonathan.hughes@norr.com | N2: 416 944 7837 | O2: 175 Bloor Street East, Toronto, Ontario, M4W 3R8, CA | P2: Ricardo Avila | Q2: Senior Principal, Retail | U2: Anthony Ricciuti | V2: Executive Vice President, Retail | Z2: Andrea Davis | AA2: Principal, Retail | AE2: How can | AF2: Vice President, Operations, US
A3: GPD Group | B3: 28064000 | C3: 14364000 | H3: 42428000 | I3: 705 | J3: BDC 2023 | K3: Jeff Evans | L3: Senior Vice President, Operations | P3: Becky McAdams | Q3: Vice President, Operations | U3: Trever Powers | V3: Vice President, Operations | Z3: Jake Bendik | AA3: Director, Retail/Commercial | AE3: Steve Turner | AF3: National Leader, Strategy and Growth, Multi Site Programs
A4: HFA | I4: 670 | J4: ICSC CB | K4: Ryan Ray | L4: Chief Operating Officer | P4: Aksel Solberg | Q4: Design Development Studio Lead | U4: James Owens | V4: Vice President | Z4: Bo Ebbrecht | AA4: Vice President | AE4: Marc Jennings | AF4: Vice President
A5: H2M Architects + Engineers | I5: 629 | J5: ICSC CB | K5: Joseph Mottola | L5: Chief Operating Officer | P5: Ray Givargis | Q5: Studio Director | U5: Phil Schade | V5: Senior Vice President, Market Director, Energy
A6: WATG | D6: 5653143 | G6: 77924699 | H6: 83577842 | I6: 577 | J6: BDC 2023
A7: HED | D7: 9426600 | E7: 4600000 | F7: 20200000 | H7: 34226600 | I7: 575 | J7: BDC 2023 | K7: Michael Cooper | L7: President | P7: Anna McDougall | Q7: Principal, Operations Practice Leader | U7: Jerome (Otis) Odell | V7: Principal, Business Leader, Housing and Mixed Use
A8: KTGY | B8: 3736599 | D8: 16117830 | G8: 6742437 | H8: 26596866 | I8: 514 | J8: BDC 2023 | K8: David Senden | L8: Principal | P8: Keith Labus | Q8: Principal | U8: Adam Hale | V8: Director, Production | Z8: Bindiya Agarwal | AA8: Director, Production | AE8: Brandon Wernli | AF8: Executive Director, Production
A9: Cushing Terrell | B9: 26457330 | D9: 6241505 | E9: 2391131 | F9: 2705244 | H9: 37795210 | I9: 508 | J9: BDC 2023 | K9: Martin Byrnes | L9: Chief Operating Officer | P9: Nicole Dovel-Moore | Q9: Associate Principal | U9: Joshua Hersel | V9: Director, Multi-Family Design | Z9: Brad Sperry | AA9: Principal, Design Director | AE9: Rob Arthur | AF9: Principal, Design Director
A10: Little | I10: 500 | J10: ICSC CB | K10: Charles Todd | L10: Chief Operating Officer | P10: Sarah Curtis | Q10: Principal | U10: Michael Magee | V10: Principal | Z10: Heather Nifong | AA10: Principal | AE10: John Quinn | AF10: Principal
A11: MG2 - WHAT NOW THAT IT IS CED?? | B11: 38313224 | D11: 4845824 | E11: 3022289 | H11: 46181337 | I11: 498 | J11: BDC 2023
A12: BL Companies | I12: 494 | J12: ICSC CB | K12: Derek Kohl | L12: VP of Operations | P12: Bill Fries | Q12: Director, Project Development | U12: Barbara Joslin | V12: Director, Project Development | Z12: Amy Samuelson | AA12: Executive Director of Architecture and Building Engineering | AE12: Ian McPhillips | AF12: Director, Energy
A13: LS3P Associates | B13: 5964397 | C13: 2586784 | D13: 12355944 | E13: 7373084 | G13: 2798008 | H13: 31078217 | I13: 488 | J13: BDC 2023 | K13: George Temple | L13: Chief Operating Officer | P13: Neil Dawson | Q13: Living Practice Leader | U13: Chris Owings | V13: Senior Practice Professional, Urban Environments | Z13: David Burt | AA13: Firmwide Hospitality Sector Leader / Vice President | AE13: Roy Selvidge | AF13: Firmwide Federal & Industrial Sector Leader
A14: Larson Design Group | I14: 472 | J14: ICSC CB | K14: David Schaarsmith | L14: Chief Operating Officer | P14: Ronald Kretz | Q14: Built Environment Operations Manager and Vice President | U14: Andrew Dorin | V14: Market Lead & Vice President
A15: AO | B15: 35332000 | C15: 1752000 | D15: 52485000 | E15: 8187000 | F15: 1944000 | G15: 6903000 | H15: 106603000 | I15: 446 | J15: BDC 2023 | P15: Rob Budetti | Q15: Managing Partner | U15: Jeff Rabbitt | V15: Partner | Z15: Richard Clark | AA15: Partner | AE15: RC Alley | AF15: Managing Partner
A16: Moody Nolan | B16: 6334173 | D16: 13233668 | H16: 19567841 | I16: 375 | J16: BDC 2023 | K16: Allen Schaffer | L16: Partner, Chief Operating Office, Chief Sustainability Officer | P16: Todd Dove | Q16: Partner, Retail Practice Leader | U16: Yanitza Brongers-Marrero | V16: Partner, Housing Practice Leader | Z16: Jay Boone | AA16: Partner, Director of General Architecture | AE16: Julie Cook | AF16: Partner, Director of Project Delivery
A17: Progressive Companies | I17: 374 | J17: ICSC CB | K17: Wes Jones | L17: Managing Principal | P17: Ryan Doherty | Q17: Principal, Mixed-use Practice Leader | U17: Doug Wurl | V17: Principal, Director of Program Delivery | Z17: Bill Culhane | AA17: Principal, Director of Project Delivery | AE17: Rand Harder | AF17: Senior Design Architect
A18: Hord Coplan Macht | D18: 26297448 | H18: 26297448 | I18: 360 | J18: BDC 2023 | K18: Joe Schneider | L18: Managing Principal | P18: John Harris | Q18: Managing Principal | U18: Liz Peterson | V18: Principal
A19: WDG | D19: 23937000 | H19: 23937000 | I19: 327 | J19: BDC 2023 | K19: Robyn Jacobson | L19: Managing Principal | P19: Siti Abdul-Rahman | Q19: Managing Principal | U19: Will Duncan | V19: Managing Principal | Z19: Doug James | AA19: Principal | AE19: Eric Schlegel | AF19: Principal
A20: Cooper Carry | B20: 9394769 | C20: 4625642 | D20: 23705448 | F20: 1656006 | G20: 19400953 | H20: 58782818 | I20: 316 | J20: BDC 2023 | K20: Kyle Reis | L20: Principal, President and CEO | P20: John Ward | Q20: Principal | U20: Angelo Carusi | V20: Principal, Atlanta Office Managing Director | Z20: Alex Lopatynsky | AA20: Principal, New York Office Managing Director | AE20: Kathy Logan | AF20: Principal
A21: Galloway & Company, Inc | I21: 313 | J21: ICSC CB | K21: Darren Bruns | L21: Chief Operating Officer | P21: Kristoffer Kenton | Q21: Director of Architecture, Principal | U21: Chris Carlson | V21: Regional Architectural Team Manager, Principal | Z21: Gary Rhodes | AA21: Regional Architectural Team Manager, Principal | AE21: Blake Olson | AF21: Architectural Project Manager, Principal
A22: Greenberg Farrow | B22: 37688000 | C22: 14560000 | H22: 52248000 | I22: 302 | J22: BDC 2023 | K22: Rodeny E. Abney, Jr | L22: CFO, Senior Vice President | P22: Ali Yadegari | Q22: Managing Director of Roll-Out Architecture | U22: Krista Karlson | V22: Managing Director of Charlotte | Z22: Kelly Hosack | AA22: Managing Director of Charleston | AE22: Mike Haas | AF22: Managing Director of Structural Engineering
A23: Cuningham | B23: 15220694 | C23: 5556771 | D23: 6149658 | H23: 26927123 | I23: 294 | J23: BDC 2023 | K23: Dan Olic | L23: Principal, Chief Operating Officer | P23: Charles Stoffel | Q23: Principal, Director of Technical Design & Delivery | U23: Gregory Houck | V23: Principal | Z23: Jeremy Agraz | AA23: Associate Principal, Executive Director - Marketing + Strategy | AE23: Jeffrey Mandyck | AF23: Director of Strategy
A24: BSB Design | D24: 24639893 | H24: 24639893 | I24: 286 | J24: BDC 2023 | K24: Chris Jorgensen | L24: Vice President of Operations | P24: Deena A. Roumeliotis | Q24: Associate, Director of Production | U24: Michael Tripodi | V24: Associate, Director of Production | Z24: Paul Penman | AA24: Associate, Director of Production | AE24: Chris Blackburn | AF24: Associate, Director of Production
A25: Solomon Cordwell Buenz (SCB) | D25: 64982137 | G25: 11891646 | H25: 76873783 | I25: 257 | J25: BDC 2023 | K25: Renee Sprogis-Marohn | L25: Chief Operating Officer
A26: Mithun | D26: 14496274 | H26: 14496274 | I26: 249 | J26: BDC 2023 | K26: Dave Goldberg | L26: President | P26: Jason Steiner | Q26: Partner
A27: Vocon | B27: 7884889 | D27: 8348706 | H27: 16233595 | I27: 245 | J27: BDC 2023 | K27: Laura Rees | L27: Chief Operating Officer
A28: Cuhaci Peterson | I28: 235 | J28: ICSC CB
A29: Benchmark Group | I29: 234 | J29: ICSC CB
A30: LRK | D30: 16700000 | H30: 16700000 | I30: 231 | J30: BDC 2023 | K30: Tony Pellicciotti | L30: Managing Principal
A31: RATIO Design | B31: 3122293 | C31: 3112262 | D31: 10357542 | G31: 7535753 | H31: 24127850 | I31: 227 | J31: BDC 2023 | K31: Bill Browne | L31: Principal, CEO | P31: Chris Meier | Q31: Principal / Dir. of Ops & Indianaplois Studio Leader | U31: Hal Bowen | V31: Principal / Raleigh Studio Leader | Z31: Clay Markham | AA31: Principal | AE31: Eric Doner | AF31: Associate Principal
A32: Dahlin Architecture | Planning | Interiors | D32: 22500000 | H32: 22500000 | I32: 224 | J32: BDC 2023 | K32: Emily A. Bonato | L32: Chief Operating Officer | P32: Lauren Jessup-Mosu | Q32: Managing Director - Regional | U32: Sean Whitacre | V32: Senior Principal / Senior Architect | Z32: Lauri Moffet-Fehlberg | AA32: Senior Vice President - Architecture | AE32: Andrew "Jack" Gallagher | AF32: Managing Principal - Austin Office
A33: Baskervill | G33: 14381252 | H33: 14381252 | I33: 223 | J33: BDC 2023 | K33: Bob Clark | L33: CEO | P33: Brad Richards | Q33: Principal, Executive Vice President | U33: Jay Woodburn | V33: Principal | Z33: Terri Callaway | AA33: Principal | AE33: Fred Hopkins | AF33: Associate, Studio Director
A34: JCJ Architecture | G34: 12039538 | H34: 12039538 | I34: 218 | J34: BDC 2023 | K34: Scott Celella | L34: Chief Operating Officer | P34: Robert Gdowski | Q34: Principal, Director of Hospitality Design | U34: Paul Hamel | V34: Director of Project Management | Z34: Jeanne Muscolino | AA34: Principal, Hospitality Market Leader | AE34: Doug Roberts | AF34: Principal
A35: Elkus Manfredi Architects | D35: 8092756 | G35: 3109129 | H35: 11201885 | I35: 210 | J35: BDC 2023

Sheet 2023 Tier 2
A1: Firm Name | B1: Retail Revenue | C1: Rest. Revenue | D1: Multifamily Revenue | E1: Industrial Revenue | F1: Data Center Revenue | G1: Hospitality Revenue | H1: Total Relevant Revenue | I1: LI Employees | J1: Data Source
A2: LEO A DALY | D2: 5358661 | E2: 12533614 | G2: 6707417 | H2: 24599692 | I2: 662 | J2: BDC 2023
A3: Barge Design Solutions | E3: 14719106 | H3: 14719106 | I3: 590 | J3: BDC 2023
A4: Little Diversified Architectural Consulting | B4: 20500780 | H4: 20500780 | I4: 501 | J4: BDC 2023
A5: Larson Design Group | B5: 17034210 | E5: 3536384 | H5: 20570594 | I5: 472 | J5: BDC 2023
A6: Ayres Associates | I6: 451 | J6: ICSC CB
A7: Moseley Architects | D7: 7212951 | H7: 7212951 | I7: 346 | J7: BDC 2023
A8: McMillan Pazdan Smith | C8: 1489679 | D8: 4330414 | E8: 7286299 | H8: 13106392 | I8: 331 | J8: BDC 2023
A9: BRR | I9: 325 | J9: ICSC CB
A10: Diamond Schmitt Architects | D10: 9127020 | H10: 9127020 | I10: 296 | J10: BDC 2023
A11: LHB | D11: 3793785 | E11: 3156753 | H11: 6950538 | I11: 269 | J11: BDC 2023
A12: TPG Architecture | B12: 10474000 | H12: 10474000 | I12: 258 | J12: BDC 2023
A13: Quinn Evans | D13: 8798319 | H13: 8798319 | I13: 249 | J13: BDC 2023
A14: BHDP Architecture | E14: 7015353 | H14: 7015353 | I14: 233 | J14: BDC 2023
A15: Handel Architects | D15: 42523884 | H15: 42523884 | I15: 194 | J15: BDC 2023
A16: Lord Aeck Sargent Planning & Design | D16: 10019663 | H16: 10019663 | I16: 188 | J16: BDC 2023
A17: Dwell Design Studio | D17: 43081125 | H17: 43081125 | I17: 186 | J17: BDC 2023
A18: Tait & Associates | I18: 184 | J18: ICSC CB
A19: RDC-S111 | B19: 25546137 | H19: 25546137 | I19: 180 | J19: BDC 2023
A20: Cromwell Architects Engineers | E20: 7744669 | H20: 7744669 | I20: 166 | J20: BDC 2023
A21: FSB Architects + Engineers | E21: 3530805 | G21: 2478377 | H21: 6009182 | I21: 164 | J21: BDC 2023
A22: Niles Bolton Associates | D22: 34215698 | H22: 34215698 | I22: 159 | J22: BDC 2023
A23: Dattner Architects | D23: 11698012 | H23: 11698012 | I23: 151 | J23: BDC 2023
A24: BAR Architects & Interiors | D24: 7825225 | H24: 7825225 | I24: 150 | J24: BDC 2023
A25: AHL | D25: 7475496 | H25: 7475496 | I25: 150 | J25: BDC 2023
A26: Aria Group Architects | B26: 15444024 | C26: 10034876 | H26: 25478900 | I26: 149 | J26: BDC 2023
A27: Cyntergy AEC | I27: 148 | J27: ICSC CB
A28: Orcutt | Winslow | B28: 5454072 | G28: 2870564 | H28: 8324636 | I28: 142 | J28: BDC 2023
A29: LK Architecture | B29: 15400000 | C29: 2200000 | G29: 3100000 | H29: 20700000 | I29: 141 | J29: BDC 2023
A30: HBG Design | G30: 20074000 | H30: 20074000 | I30: 137 | J30: BDC 2023
A31: Onyx Creative | B31: 16800000 | H31: 16800000 | I31: 131 | J31: BDC 2023
A32: SWBR | D32: 7648521 | H32: 7648521 | I32: 127 | J32: BDC 2023
A33: Chipman Design Architecture | B33: 22300000 | C33: 16300000 | H33: 38600000 | I33: 126 | J33: BDC 2023
A34: BDG Architects | I34: 124 | J34: ICSC CB
A35: FitzGerald | D35: 7138000 | H35: 7138000 | I35: 120 | J35: BDC 2023
A36: GGLO | D36: 19260795 | H36: 19260795 | I36: 116 | J36: BDC 2023
A37: Bergmeyer | B37: 11205939 | C37: 2316366 | D37: 2901318 | H37: 16423623 | I37: 116 | J37: BDC 2023
A38: Smallwood | D38: 11036238 | G38: 8257494 | H38: 19293732 | I38: 114 | J38: BDC 2023
A39: Fogarty Finger | D39: 6420000 | H39: 6420000 | I39: 113 | J39: BDC 2023
A40: GFF | B40: 3905177 | D40: 17003201 | H40: 20908378 | I40: 108 | J40: BDC 2023
...

Sheet 2023 Tier 3
A1: Firm Name | B1: Retail Revenue | C1: Rest. Revenue | D1: Multifamily Revenue | E1: Industrial Revenue | F1: Data Center Revenue | G1: Hospitality Revenue | H1: Total Relevant Revenue | I1: LI Employees | J1: Data Source
A2: HDR | F2: 100780000 | G2: 2700000 | H2: 103480000 | I2: 14915 | J2: BDC 2023
A3: Perkins&Will | B3: 6039334 | D3: 15509875 | G3: 10311923 | H3: 31861132 | I3: 2756 | J3: BDC 2023
A4: HKS | D4: 37000000 | F4: 17000000 | G4: 72000000 | H4: 126000000 | I4: 2340 | J4: BDC 2023
A5: Skidmore, Owings & Merrill | D5: 17578000 | G5: 7070000 | H5: 24648000 | I5: 1914 | J5: BDC 2023
A6: Page Southerland Page | D6: 17556240 | E6: 7745400 | F6: 27108900 | G6: 5163600 | H6: 57574140 | I6: 1902 | J6: BDC 2023
A7: Barton Malow | E7: 16001999 | H7: 16001999 | I7: 1902 | J7: BDC 2023
A8: DLR Group | B8: 21300000 | G8: 24440000 | H8: 45740000 | I8: 1820 | J8: BDC 2023
A9: Ryan Companies US | D9: 6490000 | E9: 18270000 | H9: 24760000 | I9: 1765 | J9: BDC 2023
A10: Gresham Smith | D10: 5730332 | E10: 54916599 | H10: 60646931 | I10: 1362 | J10: BDC 2023
A11: Kohn Pedersen Fox | B11: 5041570 | D11: 15846873 | G11: 5226972 | H11: 26115415 | I11: 1308 | J11: BDC 2023
A12: Corgan | F12: 122647818 | H12: 122647818 | I12: 1197 | J12: BDC 2023
A13: Perkins Eastman | G13: 17596156 | H13: 17596156 | I13: 1046 | J13: BDC 2023
A14: Whitman, Requardt & Associates | F14: 5456796 | H14: 5456796 | I14: 726 | J14: BDC 2023
A15: Goodwyn Mills Cawood | B15: 3470373 | E15: 3796954 | H15: 7267327 | I15: 572 | J15: BDC 2023

Sheet Firm Engagement
A1: FIRM | B1: Notes | J1: plant | K1: water bottle | N1: Engaged = 1
A2: NORR | C2: Andrea Davis | D2: Anthony Ricciuit | N2: 1
A3: GPD Group | C3: Becky McAdams | D3: Steve Turner | E3: Jake Bendik | F3: Trever Powers | G3: Jeff Evans | N3: 1
A4: HFA | C4: Bo Ebbrecht | D4: Aksel | E4: Nicole Bell | N4: 1
A5: H2M Architects + Engineers | C5: Jim Powers | D5: Raymond Givargis | N5: 1
A6: ADA Architects | C6: Brian Quinn | D6: James Kassay | E6: Lindsay Scott | N6: 1
A7: WATG | C7: Richard Luis | D7: Monica Cuervo | N7: 1
A8: HED | C8: Joe Furwa | N8: 1
A9: KTGY | C9: Brandon Wernli | D9: David Senden | N9: 1
A10: Cushing Terrell
A11: Little
A12: MG2 - WHAT NOW THAT IT IS CED??
A13: HP Engineering
A14: LS3P Associates
A15: Larson Design Group | C15: Andrew Dorin (changed firms) | N15: 1
A16: AO | C16: Jeff Rabbitt | D16: Johnny Hembree | M16: not interested' | N16: 1
A17: Moody Nolan | C17: Kathryn Prigmore | D17: Todd Dove | E17: Allen Schaffer | N17: 1
A18: Progressive Companies | C18: Wes Jones | D18: Ryan Doherty | N18: 1
A19: Hord Coplan Macht | C19: Tim Linko | D19: Gary Hubler | N19: 1
A20: WDG
A21: Cooper Carry | C21: Daniel Sweeney | D21: T. Jack Bagby | E21: Manny Dominguez | F21: Dots Colley | N21: 1
A22: Galloway & Company, Inc | C22: Chris Carlson | D22: Catherine Gaboian (Caty) | E22: Jenny Romano | F22: Andrew Dorin | N22: 1
A23: Greenberg Farrow | C23: Kelly Hosack | D23: Faith Hoople | N23: 1
A24: Cuningham
A25: MJM Architects | C25: Gretchen Fisher | D25: Derron Sluser | N25: 1
A26: BSB Design
A27: Silver Studio Architects (Amy's old firm) | C27: Ellen Garland | N27: 1
A28: Solomon Cordwell Buenz (SCB)
A29: Mithun
A30: Vocon
A31: Cuhaci Peterson | C31: NON TARGET | N31: 1
A32: Benchmark Group | C32: Jason Adams | D32: Jason Dodson | N32: 1
A33: LRK
A34: RATIO Design
A35: Dahlin Architecture | Planning | Interiors
A36: Baskervill | C36: Bob Clark | D36: Eric Haley | E36: Alan Davis | F36: Bob Clark | G36: Sheena Mayfield | N36: 1
A37: JCJ Architecture
A38: Elkus Manfredi Architects
A39: Cyntergy | C39: Gordy Guest (CEO) | D39: Kent Bray | E39: Seth Hildebrant | F39: Stephen Burgin | G39: Michael Hicks | H39: Linda Waytula | N39: 1
A40: LEO A DALY | C40: Cindy A. McCleary | D40: Ivan O. | N40: 1
...

Sheet Centerbuild 2024
A1: Company | B1: Score | C1: Status | D1: CIV | E1: ARC | F1: STR | G1: MP | H1: ELE | I1: FP | J1: Column6 | K1: Column5 | L1: Column4 | M1: Column3 | N1: Column2 | O1: Column1 | P1: Mkt Fit (1-3) | Q1: Size (S, M, L) | R1: Column7 | S1: TZone | T1: Column8 | U1: Low-cost office? | V1: Column9 | W1: Using Competitor?
A2: HFA | B2: =Table1[[#This Row],[Column6]]+Table1[[#This Row],[Column5]]+Table1[[#This Row],[Column4]]+Table1[[#This Row],[Column3]]+Table1[[#This Row],[Column2]]+Table1[[#This Row],[Column1]]+2*(Table1[[#This Row],[Mkt Fit (1-3)]])+Table1[[#This Row],[Column7]]+Table1[[#This Row],[Column8]]+Table1[[#This Row],[Column9]] -> 23.5 | C2: Contact | D2: ✓ | E2: ✓ | F2: ✓ | G2: ✓ | H2: ✓ | I2: ✓ | J2: =IF(Table1[[#This Row],[CIV]]="⮽",0,1)*1.5 -> 1.5 | K2: =IF(Table1[[#This Row],[ARC]]="⮽",0,1)*3 -> 3 | L2: =IF(Table1[[#This Row],[STR]]="⮽",0,1)*2 -> 2 | M2: =IF(Table1[[#This Row],[MP]]="⮽",0,1) -> 1 | N2: =IF(Table1[[#This Row],[ELE]]="⮽",0,1) -> 1 | O2: =IF(Table1[[#This Row],[FP]]="⮽",0,1) -> 1 | P2: 3 | Q2: M | R2: =IF(Table1[[#This Row],[Size (S, M, L)]]="S",2,IF(Table1[[#This Row],[Size (S, M, L)]]="L",1,4)) -> 4 | S2: EST | T2: =IF(Table1[[#This Row],[TZone]]="EST",4,IF(Table1[[#This Row],[TZone]]="CST",3,IF(Table1[[#This Row],[TZone]]="MST",2,1))) -> 4 | U2: No | V2: =IF(Table1[[#This Row],[Low-cost office?]]="Yes",-4,0) -> 0
A3: Larson Design Group | B3: =Table1[[#This Row],[Column6]]+Table1[[#This Row],[Column5]]+Table1[[#This Row],[Column4]]+Table1[[#This Row],[Column3]]+Table1[[#This Row],[Column2]]+Table1[[#This Row],[Column1]]+2*(Table1[[#This Row],[Mkt Fit (1-3)]])+Table1[[#This Row],[Column7]]+Table1[[#This Row],[Column8]]+Table1[[#This Row],[Column9]] -> 23.5 | C3: Connection | D3: ✓ | E3: ✓ | F3: ✓ | G3: ✓ | H3: ✓ | I3: ✓ | J3: =IF(Table1[[#This Row],[CIV]]="⮽",0,1)*1.5 -> 1.5 | K3: =IF(Table1[[#This Row],[ARC]]="⮽",0,1)*3 -> 3 | L3: =IF(Table1[[#This Row],[STR]]="⮽",0,1)*2 -> 2 | M3: =IF(Table1[[#This Row],[MP]]="⮽",0,1) -> 1 | N3: =IF(Table1[[#This Row],[ELE]]="⮽",0,1) -> 1 | O3: =IF(Table1[[#This Row],[FP]]="⮽",0,1) -> 1 | P3: 3 | Q3: M | R3: =IF(Table1[[#This Row],[Size (S, M, L)]]="S",2,IF(Table1[[#This Row],[Size (S, M, L)]]="L",1,4)) -> 4 | S3: EST | T3: =IF(Table1[[#This Row],[TZone]]="EST",4,IF(Table1[[#This Row],[TZone]]="CST",3,IF(Table1[[#This Row],[TZone]]="MST",2,1))) -> 4 | U3: No | V3: =IF(Table1[[#This Row],[Low-cost office?]]="Yes",-4,0) -> 0
A4: Benchmark Group | B4: =Table1[[#This Row],[Column6]]+Table1[[#This Row],[Column5]]+Table1[[#This Row],[Column4]]+Table1[[#This Row],[Column3]]+Table1[[#This Row],[Column2]]+Table1[[#This Row],[Column1]]+2*(Table1[[#This Row],[Mkt Fit (1-3)]])+Table1[[#This Row],[Column7]]+Table1[[#This Row],[Column8]]+Table1[[#This Row],[Column9]] -> 22.5 | C4: Contact | D4: ✓ | E4: ✓ | F4: ✓ | G4: ✓ | H4: ✓ | I4: ✓ | J4: =IF(Table1[[#This Row],[CIV]]="⮽",0,1)*1.5 -> 1.5 | K4: =IF(Table1[[#This Row],[ARC]]="⮽",0,1)*3 -> 3 | L4: =IF(Table1[[#This Row],[STR]]="⮽",0,1)*2 -> 2 | M4: =IF(Table1[[#This Row],[MP]]="⮽",0,1) -> 1 | N4: =IF(Table1[[#This Row],[ELE]]="⮽",0,1) -> 1 | O4: =IF(Table1[[#This Row],[FP]]="⮽",0,1) -> 1 | P4: 3 | Q4: M | R4: =IF(Table1[[#This Row],[Size (S, M, L)]]="S",2,IF(Table1[[#This Row],[Size (S, M, L)]]="L",1,4)) -> 4 | S4: CST | T4: =IF(Table1[[#This Row],[TZone]]="EST",4,IF(Table1[[#This Row],[TZone]]="CST",3,IF(Table1[[#This Row],[TZone]]="MST",2,1))) -> 3 | U4: No | V4: =IF(Table1[[#This Row],[Low-cost office?]]="Yes",-4,0) -> 0
A5: Core States Group | B5: =Table1[[#This Row],[Column6]]+Table1[[#This Row],[Column5]]+Table1[[#This Row],[Column4]]+Table1[[#This Row],[Column3]]+Table1[[#This Row],[Column2]]+Table1[[#This Row],[Column1]]+2*(Table1[[#This Row],[Mkt Fit (1-3)]])+Table1[[#This Row],[Column7]]+Table1[[#This Row],[Column8]]+Table1[[#This Row],[Column9]] -> 22.5 | C5: Client | D5: ✓ | E5: ✓ | F5: ✓ | G5: ✓ | H5: ✓ | I5: ✓ | J5: =IF(Table1[[#This Row],[CIV]]="⮽",0,1)*1.5 -> 1.5 | K5: =IF(Table1[[#This Row],[ARC]]="⮽",0,1)*3 -> 3 | L5: =IF(Table1[[#This Row],[STR]]="⮽",0,1)*2 -> 2 | M5: =IF(Table1[[#This Row],[MP]]="⮽",0,1) -> 1 | N5: =IF(Table1[[#This Row],[ELE]]="⮽",0,1) -> 1 | O5: =IF(Table1[[#This Row],[FP]]="⮽",0,1) -> 1 | P5: 3 | Q5: M | R5: =IF(Table1[[#This Row],[Size (S, M, L)]]="S",2,IF(Table1[[#This Row],[Size (S, M, L)]]="L",1,4)) -> 4 | S5: CST | T5: =IF(Table1[[#This Row],[TZone]]="EST",4,IF(Table1[[#This Row],[TZone]]="CST",3,IF(Table1[[#This Row],[TZone]]="MST",2,1))) -> 3 | U5: No | V5: =IF(Table1[[#This Row],[Low-cost office?]]="Yes",-4,0) -> 0
A6: GreenbergFarrow | B6: =Table1[[#This Row],[Column6]]+Table1[[#This Row],[Column5]]+Table1[[#This Row],[Column4]]+Table1[[#This Row],[Column3]]+Table1[[#This Row],[Column2]]+Table1[[#This Row],[Column1]]+2*(Table1[[#This Row],[Mkt Fit (1-3)]])+Table1[[#This Row],[Column7]]+Table1[[#This Row],[Column8]]+Table1[[#This Row],[Column9]] -> 22.5 | C6: Target | D6: ✓ | E6: ✓ | F6: ✓ | G6: ✓ | H6: ✓ | I6: ⮽ | J6: =IF(Table1[[#This Row],[CIV]]="⮽",0,1)*1.5 -> 1.5 | K6: =IF(Table1[[#This Row],[ARC]]="⮽",0,1)*3 -> 3 | L6: =IF(Table1[[#This Row],[STR]]="⮽",0,1)*2 -> 2 | M6: =IF(Table1[[#This Row],[MP]]="⮽",0,1) -> 1 | N6: =IF(Table1[[#This Row],[ELE]]="⮽",0,1) -> 1 | O6: =IF(Table1[[#This Row],[FP]]="⮽",0,1) -> 0 | P6: 3 | Q6: M | R6: =IF(Table1[[#This Row],[Size (S, M, L)]]="S",2,IF(Table1[[#This Row],[Size (S, M, L)]]="L",1,4)) -> 4 | S6: EST | T6: =IF(Table1[[#This Row],[TZone]]="EST",4,IF(Table1[[#This Row],[TZone]]="CST",3,IF(Table1[[#This Row],[TZone]]="MST",2,1))) -> 4 | U6: No | V6: =IF(Table1[[#This Row],[Low-cost office?]]="Yes",-4,0) -> 0
A7: BL Companies | B7: =Table1[[#This Row],[Column6]]+Table1[[#This Row],[Column5]]+Table1[[#This Row],[Column4]]+Table1[[#This Row],[Column3]]+Table1[[#This Row],[Column2]]+Table1[[#This Row],[Column1]]+2*(Table1[[#This Row],[Mkt Fit (1-3)]])+Table1[[#This Row],[Column7]]+Table1[[#This Row],[Column8]]+Table1[[#This Row],[Column9]] -> 21.5 | C7: Contact | D7: ✓ | E7: ✓ | F7: ✓ | G7: ✓ | H7: ✓ | I7: ✓ | J7: =IF(Table1[[#This Row],[CIV]]="⮽",0,1)*1.5 -> 1.5 | K7: =IF(Table1[[#This Row],[ARC]]="⮽",0,1)*3 -> 3 | L7: =IF(Table1[[#This Row],[STR]]="⮽",0,1)*2 -> 2 | M7: =IF(Table1[[#This Row],[MP]]="⮽",0,1) -> 1 | N7: =IF(Table1[[#This Row],[ELE]]="⮽",0,1) -> 1 | O7: =IF(Table1[[#This Row],[FP]]="⮽",0,1) -> 1 | P7: 2 | Q7: M | R7: =IF(Table1[[#This Row],[Size (S, M, L)]]="S",2,IF(Table1[[#This Row],[Size (S, M, L)]]="L",1,4)) -> 4 | S7: EST | T7: =IF(Table1[[#This Row],[TZone]]="EST",4,IF(Table1[[#This Row],[TZone]]="CST",3,IF(Table1[[#This Row],[TZone]]="MST",2,1))) -> 4 | U7: No | V7: =IF(Table1[[#This Row],[Low-cost office?]]="Yes",-4,0) -> 0
A8: CESO | B8: =Table1[[#This Row],[Column6]]+Table1[[#This Row],[Column5]]+Table1[[#This Row],[Column4]]+Table1[[#This Row],[Column3]]+Table1[[#This Row],[Column2]]+Table1[[#This Row],[Column1]]+2*(Table1[[#This Row],[Mkt Fit (1-3)]])+Table1[[#This Row],[Column7]]+Table1[[#This Row],[Column8]]+Table1[[#This Row],[Column9]] -> 21.5 | C8: Client | D8: ✓ | E8: ✓ | F8: ✓ | G8: ✓ | H8: ✓ | I8: ⮽ | J8: =IF(Table1[[#This Row],[CIV]]="⮽",0,1)*1.5 -> 1.5 | K8: =IF(Table1[[#This Row],[ARC]]="⮽",0,1)*3 -> 3 | L8: =IF(Table1[[#This Row],[STR]]="⮽",0,1)*2 -> 2 | M8: =IF(Table1[[#This Row],[MP]]="⮽",0,1) -> 1 | N8: =IF(Table1[[#This Row],[ELE]]="⮽",0,1) -> 1 | O8: =IF(Table1[[#This Row],[FP]]="⮽",0,1) -> 0 | P8: 3 | Q8: M | R8: =IF(Table1[[#This Row],[Size (S, M, L)]]="S",2,IF(Table1[[#This Row],[Size (S, M, L)]]="L",1,4)) -> 4 | S8: CST | T8: =IF(Table1[[#This Row],[TZone]]="EST",4,IF(Table1[[#This Row],[TZone]]="CST",3,IF(Table1[[#This Row],[TZone]]="MST",2,1))) -> 3 | U8: No | V8: =IF(Table1[[#This Row],[Low-cost office?]]="Yes",-4,0) -> 0
A9: H2M Architects + Engineers | B9: =Table1[[#This Row],[Column6]]+Table1[[#This Row],[Column5]]+Table1[[#This Row],[Column4]]+Table1[[#This Row],[Column3]]+Table1[[#This Row],[Column2]]+Table1[[#This Row],[Column1]]+2*(Table1[[#This Row],[Mkt Fit (1-3)]])+Table1[[#This Row],[Column7]]+Table1[[#This Row],[Column8]]+Table1[[#This Row],[Column9]] -> 21.5 | C9: Target | D9: ✓ | E9: ✓ | F9: ✓ | G9: ✓ | H9: ✓ | I9: ✓ | J9: =IF(Table1[[#This Row],[CIV]]="⮽",0,1)*1.5 -> 1.5 | K9: =IF(Table1[[#This Row],[ARC]]="⮽",0,1)*3 -> 3 | L9: =IF(Table1[[#This Row],[STR]]="⮽",0,1)*2 -> 2 | M9: =IF(Table1[[#This Row],[MP]]="⮽",0,1) -> 1 | N9: =IF(Table1[[#This Row],[ELE]]="⮽",0,1) -> 1 | O9: =IF(Table1[[#This Row],[FP]]="⮽",0,1) -> 1 | P9: 2 | Q9: M | R9: =IF(Table1[[#This Row],[Size (S, M, L)]]="S",2,IF(Table1[[#This Row],[Size (S, M, L)]]="L",1,4)) -> 4 | S9: EST | T9: =IF(Table1[[#This Row],[TZone]]="EST",4,IF(Table1[[#This Row],[TZone]]="CST",3,IF(Table1[[#This Row],[TZone]]="MST",2,1))) -> 4 | U9: No | V9: =IF(Table1[[#This Row],[Low-cost office?]]="Yes",-4,0) -> 0
A10: Little | B10: =Table1[[#This Row],[Column6]]+Table1[[#This Row],[Column5]]+Table1[[#This Row],[Column4]]+Table1[[#This Row],[Column3]]+Table1[[#This Row],[Column2]]+Table1[[#This Row],[Column1]]+2*(Table1[[#This Row],[Mkt Fit (1-3)]])+Table1[[#This Row],[Column7]]+Table1[[#This Row],[Column8]]+Table1[[#This Row],[Column9]] -> 21 | C10: Contact | D10: ⮽ | E10: ✓ | F10: ✓ | G10: ✓ | H10: ✓ | I10: ⮽ | J10: =IF(Table1[[#This Row],[CIV]]="⮽",0,1)*1.5 -> 0 | K10: =IF(Table1[[#This Row],[ARC]]="⮽",0,1)*3 -> 3 | L10: =IF(Table1[[#This Row],[STR]]="⮽",0,1)*2 -> 2 | M10: =IF(Table1[[#This Row],[MP]]="⮽",0,1) -> 1 | N10: =IF(Table1[[#This Row],[ELE]]="⮽",0,1) -> 1 | O10: =IF(Table1[[#This Row],[FP]]="⮽",0,1) -> 0 | P10: 3 | Q10: M | R10: =IF(Table1[[#This Row],[Size (S, M, L)]]="S",2,IF(Table1[[#This Row],[Size (S, M, L)]]="L",1,4)) -> 4 | S10: EST | T10: =IF(Table1[[#This Row],[TZone]]="EST",4,IF(Table1[[#This Row],[TZone]]="CST",3,IF(Table1[[#This Row],[TZone]]="MST",2,1))) -> 4 | U10: No | V10: =IF(Table1[[#This Row],[Low-cost office?]]="Yes",-4,0) -> 0
A11: Cyntergy AEC | B11: =Table1[[#This Row],[Column6]]+Table1[[#This Row],[Column5]]+Table1[[#This Row],[Column4]]+Table1[[#This Row],[Column3]]+Table1[[#This Row],[Column2]]+Table1[[#This Row],[Column1]]+2*(Table1[[#This Row],[Mkt Fit (1-3)]])+Table1[[#This Row],[Column7]]+Table1[[#This Row],[Column8]]+Table1[[#This Row],[Column9]] -> 20.5 | C11: Target | D11: ✓ | E11: ✓ | F11: ✓ | G11: ✓ | H11: ✓ | I11: ✓ | J11: =IF(Table1[[#This Row],[CIV]]="⮽",0,1)*1.5 -> 1.5 | K11: =IF(Table1[[#This Row],[ARC]]="⮽",0,1)*3 -> 3 | L11: =IF(Table1[[#This Row],[STR]]="⮽",0,1)*2 -> 2 | M11: =IF(Table1[[#This Row],[MP]]="⮽",0,1) -> 1 | N11: =IF(Table1[[#This Row],[ELE]]="⮽",0,1) -> 1 | O11: =IF(Table1[[#This Row],[FP]]="⮽",0,1) -> 1 | P11: 3 | Q11: S | R11: =IF(Table1[[#This Row],[Size (S, M, L)]]="S",2,IF(Table1[[#This Row],[Size (S, M, L)]]="L",1,4)) -> 2 | S11: CST | T11: =IF(Table1[[#This Row],[TZone]]="EST",4,IF(Table1[[#This Row],[TZone]]="CST",3,IF(Table1[[#This Row],[TZone]]="MST",2,1))) -> 3 | U11: No | V11: =IF(Table1[[#This Row],[Low-cost office?]]="Yes",-4,0) -> 0
A12: Galloway & Company, Inc | B12: =Table1[[#This Row],[Column6]]+Table1[[#This Row],[Column5]]+Table1[[#This Row],[Column4]]+Table1[[#This Row],[Column3]]+Table1[[#This Row],[Column2]]+Table1[[#This Row],[Column1]]+2*(Table1[[#This Row],[Mkt Fit (1-3)]])+Table1[[#This Row],[Column7]]+Table1[[#This Row],[Column8]]+Table1[[#This Row],[Column9]] -> 20.5 | C12: Target | D12: ✓ | E12: ✓ | F12: ✓ | G12: ✓ | H12: ✓ | I12: ⮽ | J12: =IF(Table1[[#This Row],[CIV]]="⮽",0,1)*1.5 -> 1.5 | K12: =IF(Table1[[#This Row],[ARC]]="⮽",0,1)*3 -> 3 | L12: =IF(Table1[[#This Row],[STR]]="⮽",0,1)*2 -> 2 | M12: =IF(Table1[[#This Row],[MP]]="⮽",0,1) -> 1 | N12: =IF(Table1[[#This Row],[ELE]]="⮽",0,1) -> 1 | O12: =IF(Table1[[#This Row],[FP]]="⮽",0,1) -> 0 | P12: 3 | Q12: M | R12: =IF(Table1[[#This Row],[Size (S, M, L)]]="S",2,IF(Table1[[#This Row],[Size (S, M, L)]]="L",1,4)) -> 4 | S12: MST | T12: =IF(Table1[[#This Row],[TZone]]="EST",4,IF(Table1[[#This Row],[TZone]]="CST",3,IF(Table1[[#This Row],[TZone]]="MST",2,1))) -> 2 | U12: No | V12: =IF(Table1[[#This Row],[Low-cost office?]]="Yes",-4,0) -> 0
A13: Progressive Companies | B13: =Table1[[#This Row],[Column6]]+Table1[[#This Row],[Column5]]+Table1[[#This Row],[Column4]]+Table1[[#This Row],[Column3]]+Table1[[#This Row],[Column2]]+Table1[[#This Row],[Column1]]+2*(Table1[[#This Row],[Mkt Fit (1-3)]])+Table1[[#This Row],[Column7]]+Table1[[#This Row],[Column8]]+Table1[[#This Row],[Column9]] -> 20.5 | C13: Connection | D13: ✓ | E13: ✓ | F13: ✓ | G13: ✓ | H13: ✓ | I13: ⮽ | J13: =IF(Table1[[#This Row],[CIV]]="⮽",0,1)*1.5 -> 1.5 | K13: =IF(Table1[[#This Row],[ARC]]="⮽",0,1)*3 -> 3 | L13: =IF(Table1[[#This Row],[STR]]="⮽",0,1)*2 -> 2 | M13: =IF(Table1[[#This Row],[MP]]="⮽",0,1) -> 1 | N13: =IF(Table1[[#This Row],[ELE]]="⮽",0,1) -> 1 | O13: =IF(Table1[[#This Row],[FP]]="⮽",0,1) -> 0 | P13: 2 | Q13: M | R13: =IF(Table1[[#This Row],[Size (S, M, L)]]="S",2,IF(Table1[[#This Row],[Size (S, M, L)]]="L",1,4)) -> 4 | S13: EST | T13: =IF(Table1[[#This Row],[TZone]]="EST",4,IF(Table1[[#This Row],[TZone]]="CST",3,IF(Table1[[#This Row],[TZone]]="MST",2,1))) -> 4 | U13: No | V13: =IF(Table1[[#This Row],[Low-cost office?]]="Yes",-4,0) -> 0
... A45: DLR Group | B45: =Table1[[#This Row],[Column6]]+Table1[[#This Row],[Column5]]+Table1[[#This Row],[Column4]]+Table1[[#This Row],[Column3]]+Table1[[#This Row],[Column2]]+Table1[[#This Row],[Column1]]+2*(Table1[[#This Row],[Mkt Fit (1-3)]])+Table1[[#This Row],[Column7]]+Table1[[#This Row],[Column8]]+Table1[[#This Row],[Column9]] -> 14.5 | C45: Target | D45: ✓ | E45: ✓ | F45: ✓ | G45: ✓ | H45: ✓ | I45: ⮽ | J45: =IF(Table1[[#This Row],[CIV]]="⮽",0,1)*1.5 -> 1.5 | K45: =IF(Table1[[#This Row],[ARC]]="⮽",0,1)*3 -> 3 | L45: =IF(Table1[[#This Row],[STR]]="⮽",0,1)*2 -> 2 | M45: =IF(Table1[[#This Row],[MP]]="⮽",0,1) -> 1 | N45: =IF(Table1[[#This Row],[ELE]]="⮽",0,1) -> 1 | O45: =IF(Table1[[#This Row],[FP]]="⮽",0,1) -> 0 | P45: 1 | Q45: L | R45: =IF(Table1[[#This Row],[Size (S, M, L)]]="S",2,IF(Table1[[#This Row],[Size (S, M, L)]]="L",1,4)) -> 1 | S45: CST | T45: =IF(Table1[[#This Row],[TZone]]="EST",4,IF(Table1[[#This Row],[TZone]]="CST",3,IF(Table1[[#This Row],[TZone]]="MST",2,1))) -> 3 | U45: No | V45: =IF(Table1[[#This Row],[Low-cost office?]]="Yes",-4,0) -> 0
A46: Ensemble | B46: =Table1[[#This Row],[Column6]]+Table1[[#This Row],[Column5]]+Table1[[#This Row],[Column4]]+Table1[[#This Row],[Column3]]+Table1[[#This Row],[Column2]]+Table1[[#This Row],[Column1]]+2*(Table1[[#This Row],[Mkt Fit (1-3)]])+Table1[[#This Row],[Column7]]+Table1[[#This Row],[Column8]]+Table1[[#This Row],[Column9]] -> 14.5 | C46: Competitor | J46: =IF(Table1[[#This Row],[CIV]]="⮽",0,1)*1.5 -> 1.5 | K46: =IF(Table1[[#This Row],[ARC]]="⮽",0,1)*3 -> 3 | L46: =IF(Table1[[#This Row],[STR]]="⮽",0,1)*2 -> 2 | M46: =IF(Table1[[#This Row],[MP]]="⮽",0,1) -> 1 | N46: =IF(Table1[[#This Row],[ELE]]="⮽",0,1) -> 1 | O46: =IF(Table1[[#This Row],[FP]]="⮽",0,1) -> 1 | R46: =IF(Table1[[#This Row],[Size (S, M, L)]]="S",2,IF(Table1[[#This Row],[Size (S, M, L)]]="L",1,4)) -> 4 | T46: =IF(Table1[[#This Row],[TZone]]="EST",4,IF(Table1[[#This Row],[TZone]]="CST",3,IF(Table1[[#This Row],[TZone]]="MST",2,1))) -> 1 | V46: =IF(Table1[[#This Row],[Low-cost office?]]="Yes",-4,0) -> 0
A47: Kimley-Horn | B47: =Table1[[#This Row],[Column6]]+Table1[[#This Row],[Column5]]+Table1[[#This Row],[Column4]]+Table1[[#This Row],[Column3]]+Table1[[#This Row],[Column2]]+Table1[[#This Row],[Column1]]+2*(Table1[[#This Row],[Mkt Fit (1-3)]])+Table1[[#This Row],[Column7]]+Table1[[#This Row],[Column8]]+Table1[[#This Row],[Column9]] -> 14.5 | C47: Contact | D47: ✓ | E47: ⮽ | F47: ✓ | G47: ✓ | H47: ✓ | I47: ⮽ | J47: =IF(Table1[[#This Row],[CIV]]="⮽",0,1)*1.5 -> 1.5 | K47: =IF(Table1[[#This Row],[ARC]]="⮽",0,1)*3 -> 0 | L47: =IF(Table1[[#This Row],[STR]]="⮽",0,1)*2 -> 2 | M47: =IF(Table1[[#This Row],[MP]]="⮽",0,1) -> 1 | N47: =IF(Table1[[#This Row],[ELE]]="⮽",0,1) -> 1 | O47: =IF(Table1[[#This Row],[FP]]="⮽",0,1) -> 0 | P47: 2 | Q47: L | R47: =IF(Table1[[#This Row],[Size (S, M, L)]]="S",2,IF(Table1[[#This Row],[Size (S, M, L)]]="L",1,4)) -> 1 | S47: EST | T47: =IF(Table1[[#This Row],[TZone]]="EST",4,IF(Table1[[#This Row],[TZone]]="CST",3,IF(Table1[[#This Row],[TZone]]="MST",2,1))) -> 4 | U47: No | V47: =IF(Table1[[#This Row],[Low-cost office?]]="Yes",-4,0) -> 0
A48: RaSmith | B48: =Table1[[#This Row],[Column6]]+Table1[[#This Row],[Column5]]+Table1[[#This Row],[Column4]]+Table1[[#This Row],[Column3]]+Table1[[#This Row],[Column2]]+Table1[[#This Row],[Column1]]+2*(Table1[[#This Row],[Mkt Fit (1-3)]])+Table1[[#This Row],[Column7]]+Table1[[#This Row],[Column8]]+Table1[[#This Row],[Column9]] -> 14.5 | C48: Connection | D48: ✓ | E48: ⮽ | F48: ✓ | G48: ⮽ | H48: ⮽ | I48: ⮽ | J48: =IF(Table1[[#This Row],[CIV]]="⮽",0,1)*1.5 -> 1.5 | K48: =IF(Table1[[#This Row],[ARC]]="⮽",0,1)*3 -> 0 | L48: =IF(Table1[[#This Row],[STR]]="⮽",0,1)*2 -> 2 | M48: =IF(Table1[[#This Row],[MP]]="⮽",0,1) -> 0 | N48: =IF(Table1[[#This Row],[ELE]]="⮽",0,1) -> 0 | O48: =IF(Table1[[#This Row],[FP]]="⮽",0,1) -> 0 | P48: 2 | Q48: M | R48: =IF(Table1[[#This Row],[Size (S, M, L)]]="S",2,IF(Table1[[#This Row],[Size (S, M, L)]]="L",1,4)) -> 4 | S48: CST | T48: =IF(Table1[[#This Row],[TZone]]="EST",4,IF(Table1[[#This Row],[TZone]]="CST",3,IF(Table1[[#This Row],[TZone]]="MST",2,1))) -> 3 | U48: No | V48: =IF(Table1[[#This Row],[Low-cost office?]]="Yes",-4,0) -> 0
A49: VAA | B49: =Table1[[#This Row],[Column6]]+Table1[[#This Row],[Column5]]+Table1[[#This Row],[Column4]]+Table1[[#This Row],[Column3]]+Table1[[#This Row],[Column2]]+Table1[[#This Row],[Column1]]+2*(Table1[[#This Row],[Mkt Fit (1-3)]])+Table1[[#This Row],[Column7]]+Table1[[#This Row],[Column8]]+Table1[[#This Row],[Column9]] -> 14.5 | C49: Target | D49: ✓ | E49: ⮽ | F49: ✓ | G49: ✓ | H49: ✓ | I49: ⮽ | J49: =IF(Table1[[#This Row],[CIV]]="⮽",0,1)*1.5 -> 1.5 | K49: =IF(Table1[[#This Row],[ARC]]="⮽",0,1)*3 -> 0 | L49: =IF(Table1[[#This Row],[STR]]="⮽",0,1)*2 -> 2 | M49: =IF(Table1[[#This Row],[MP]]="⮽",0,1) -> 1 | N49: =IF(Table1[[#This Row],[ELE]]="⮽",0,1) -> 1 | O49: =IF(Table1[[#This Row],[FP]]="⮽",0,1) -> 0 | P49: 1 | Q49: M | R49: =IF(Table1[[#This Row],[Size (S, M, L)]]="S",2,IF(Table1[[#This Row],[Size (S, M, L)]]="L",1,4)) -> 4 | S49: CST | T49: =IF(Table1[[#This Row],[TZone]]="EST",4,IF(Table1[[#This Row],[TZone]]="CST",3,IF(Table1[[#This Row],[TZone]]="MST",2,1))) -> 3 | U49: No | V49: =IF(Table1[[#This Row],[Low-cost office?]]="Yes",-4,0) -> 0
A50: Woolpert Inc. | B50: =Table1[[#This Row],[Column6]]+Table1[[#This Row],[Column5]]+Table1[[#This Row],[Column4]]+Table1[[#This Row],[Column3]]+Table1[[#This Row],[Column2]]+Table1[[#This Row],[Column1]]+2*(Table1[[#This Row],[Mkt Fit (1-3)]])+Table1[[#This Row],[Column7]]+Table1[[#This Row],[Column8]]+Table1[[#This Row],[Column9]] -> 14.5 | C50: Target | D50: ✓ | E50: ✓ | F50: ✓ | G50: ✓ | H50: ✓ | I50: ⮽ | J50: =IF(Table1[[#This Row],[CIV]]="⮽",0,1)*1.5 -> 1.5 | K50: =IF(Table1[[#This Row],[ARC]]="⮽",0,1)*3 -> 3 | L50: =IF(Table1[[#This Row],[STR]]="⮽",0,1)*2 -> 2 | M50: =IF(Table1[[#This Row],[MP]]="⮽",0,1) -> 1 | N50: =IF(Table1[[#This Row],[ELE]]="⮽",0,1) -> 1 | O50: =IF(Table1[[#This Row],[FP]]="⮽",0,1) -> 0 | P50: 1 | Q50: L | R50: =IF(Table1[[#This Row],[Size (S, M, L)]]="S",2,IF(Table1[[#This Row],[Size (S, M, L)]]="L",1,4)) -> 1 | S50: CST | T50: =IF(Table1[[#This Row],[TZone]]="EST",4,IF(Table1[[#This Row],[TZone]]="CST",3,IF(Table1[[#This Row],[TZone]]="MST",2,1))) -> 3 | U50: No | V50: =IF(Table1[[#This Row],[Low-cost office?]]="Yes",-4,0) -> 0
A51: Heights Venture Architecture + Design | B51: =Table1[[#This Row],[Column6]]+Table1[[#This Row],[Column5]]+Table1[[#This Row],[Column4]]+Table1[[#This Row],[Column3]]+Table1[[#This Row],[Column2]]+Table1[[#This Row],[Column1]]+2*(Table1[[#This Row],[Mkt Fit (1-3)]])+Table1[[#This Row],[Column7]]+Table1[[#This Row],[Column8]]+Table1[[#This Row],[Column9]] -> 14 | C51: Contact | D51: ⮽ | E51: ✓ | F51: ⮽ | G51: ⮽ | H51: ⮽ | I51: ⮽ | J51: =IF(Table1[[#This Row],[CIV]]="⮽",0,1)*1.5 -> 0 | K51: =IF(Table1[[#This Row],[ARC]]="⮽",0,1)*3 -> 3 | L51: =IF(Table1[[#This Row],[STR]]="⮽",0,1)*2 -> 0 | M51: =IF(Table1[[#This Row],[MP]]="⮽",0,1) -> 0 | N51: =IF(Table1[[#This Row],[ELE]]="⮽",0,1) -> 0 | O51: =IF(Table1[[#This Row],[FP]]="⮽",0,1) -> 0 | P51: 3 | Q51: S | R51: =IF(Table1[[#This Row],[Size (S, M, L)]]="S",2,IF(Table1[[#This Row],[Size (S, M, L)]]="L",1,4)) -> 2 | S51: CST | T51: =IF(Table1[[#This Row],[TZone]]="EST",4,IF(Table1[[#This Row],[TZone]]="CST",3,IF(Table1[[#This Row],[TZone]]="MST",2,1))) -> 3 | U51: No | V51: =IF(Table1[[#This Row],[Low-cost office?]]="Yes",-4,0) -> 0
A52: Henderson Engineers, Inc | B52: =Table1[[#This Row],[Column6]]+Table1[[#This Row],[Column5]]+Table1[[#This Row],[Column4]]+Table1[[#This Row],[Column3]]+Table1[[#This Row],[Column2]]+Table1[[#This Row],[Column1]]+2*(Table1[[#This Row],[Mkt Fit (1-3)]])+Table1[[#This Row],[Column7]]+Table1[[#This Row],[Column8]]+Table1[[#This Row],[Column9]] -> 14 | C52: Target | D52: ⮽ | E52: ⮽ | F52: ⮽ | G52: ✓ | H52: ✓ | I52: ✓ | J52: =IF(Table1[[#This Row],[CIV]]="⮽",0,1)*1.5 -> 0 | K52: =IF(Table1[[#This Row],[ARC]]="⮽",0,1)*3 -> 0 | L52: =IF(Table1[[#This Row],[STR]]="⮽",0,1)*2 -> 0 | M52: =IF(Table1[[#This Row],[MP]]="⮽",0,1) -> 1 | N52: =IF(Table1[[#This Row],[ELE]]="⮽",0,1) -> 1 | O52: =IF(Table1[[#This Row],[FP]]="⮽",0,1) -> 1 | P52: 2 | Q52: M | R52: =IF(Table1[[#This Row],[Size (S, M, L)]]="S",2,IF(Table1[[#This Row],[Size (S, M, L)]]="L",1,4)) -> 4 | S52: CST | T52: =IF(Table1[[#This Row],[TZone]]="EST",4,IF(Table1[[#This Row],[TZone]]="CST",3,IF(Table1[[#This Row],[TZone]]="MST",2,1))) -> 3 | U52: No | V52: =IF(Table1[[#This Row],[Low-cost office?]]="Yes",-4,0) -> 0
A53: MCG Architecture | B53: =Table1[[#This Row],[Column6]]+Table1[[#This Row],[Column5]]+Table1[[#This Row],[Column4]]+Table1[[#This Row],[Column3]]+Table1[[#This Row],[Column2]]+Table1[[#This Row],[Column1]]+2*(Table1[[#This Row],[Mkt Fit (1-3)]])+Table1[[#This Row],[Column7]]+Table1[[#This Row],[Column8]]+Table1[[#This Row],[Column9]] -> 14 | C53: Target | D53: ⮽ | E53: ✓ | F53: ⮽ | G53: ⮽ | H53: ⮽ | I53: ⮽ | J53: =IF(Table1[[#This Row],[CIV]]="⮽",0,1)*1.5 -> 0 | K53: =IF(Table1[[#This Row],[ARC]]="⮽",0,1)*3 -> 3 | L53: =IF(Table1[[#This Row],[STR]]="⮽",0,1)*2 -> 0 | M53: =IF(Table1[[#This Row],[MP]]="⮽",0,1) -> 0 | N53: =IF(Table1[[#This Row],[ELE]]="⮽",0,1) -> 0 | O53: =IF(Table1[[#This Row],[FP]]="⮽",0,1) -> 0 | P53: 3 | Q53: S | R53: =IF(Table1[[#This Row],[Size (S, M, L)]]="S",2,IF(Table1[[#This Row],[Size (S, M, L)]]="L",1,4)) -> 2 | S53: CST | T53: =IF(Table1[[#This Row],[TZone]]="EST",4,IF(Table1[[#This Row],[TZone]]="CST",3,IF(Table1[[#This Row],[TZone]]="MST",2,1))) -> 3 | U53: No | V53: =IF(Table1[[#This Row],[Low-cost office?]]="Yes",-4,0) -> 0
A54: Nudell Architects | B54: =Table1[[#This Row],[Column6]]+Table1[[#This Row],[Column5]]+Table1[[#This Row],[Column4]]+Table1[[#This Row],[Column3]]+Table1[[#This Row],[Column2]]+Table1[[#This Row],[Column1]]+2*(Table1[[#This Row],[Mkt Fit (1-3)]])+Table1[[#This Row],[Column7]]+Table1[[#This Row],[Column8]]+Table1[[#This Row],[Column9]] -> 14 | C54: Target | D54: ⮽ | E54: ✓ | F54: ⮽ | G54: ⮽ | H54: ⮽ | I54: ⮽ | J54: =IF(Table1[[#This Row],[CIV]]="⮽",0,1)*1.5 -> 0 | K54: =IF(Table1[[#This Row],[ARC]]="⮽",0,1)*3 -> 3 | L54: =IF(Table1[[#This Row],[STR]]="⮽",0,1)*2 -> 0 | M54: =IF(Table1[[#This Row],[MP]]="⮽",0,1) -> 0 | N54: =IF(Table1[[#This Row],[ELE]]="⮽",0,1) -> 0 | O54: =IF(Table1[[#This Row],[FP]]="⮽",0,1) -> 0 | P54: 3 | Q54: S | R54: =IF(Table1[[#This Row],[Size (S, M, L)]]="S",2,IF(Table1[[#This Row],[Size (S, M, L)]]="L",1,4)) -> 2 | S54: CST | T54: =IF(Table1[[#This Row],[TZone]]="EST",4,IF(Table1[[#This Row],[TZone]]="CST",3,IF(Table1[[#This Row],[TZone]]="MST",2,1))) -> 3 | U54: No | V54: =IF(Table1[[#This Row],[Low-cost office?]]="Yes",-4,0) -> 0
A55: NWS Architects Inc. | B55: =Table1[[#This Row],[Column6]]+Table1[[#This Row],[Column5]]+Table1[[#This Row],[Column4]]+Table1[[#This Row],[Column3]]+Table1[[#This Row],[Column2]]+Table1[[#This Row],[Column1]]+2*(Table1[[#This Row],[Mkt Fit (1-3)]])+Table1[[#This Row],[Column7]]+Table1[[#This Row],[Column8]]+Table1[[#This Row],[Column9]] -> 14 | C55: Target | D55: ⮽ | E55: ✓ | F55: ⮽ | G55: ⮽ | H55: ⮽ | I55: ⮽ | J55: =IF(Table1[[#This Row],[CIV]]="⮽",0,1)*1.5 -> 0 | K55: =IF(Table1[[#This Row],[ARC]]="⮽",0,1)*3 -> 3 | L55: =IF(Table1[[#This Row],[STR]]="⮽",0,1)*2 -> 0 | M55: =IF(Table1[[#This Row],[MP]]="⮽",0,1) -> 0 | N55: =IF(Table1[[#This Row],[ELE]]="⮽",0,1) -> 0 | O55: =IF(Table1[[#This Row],[FP]]="⮽",0,1) -> 0 | P55: 3 | Q55: S | R55: =IF(Table1[[#This Row],[Size (S, M, L)]]="S",2,IF(Table1[[#This Row],[Size (S, M, L)]]="L",1,4)) -> 2 | S55: CST | T55: =IF(Table1[[#This Row],[TZone]]="EST",4,IF(Table1[[#This Row],[TZone]]="CST",3,IF(Table1[[#This Row],[TZone]]="MST",2,1))) -> 3 | U55: No | V55: =IF(Table1[[#This Row],[Low-cost office?]]="Yes",-4,0) -> 0
A56: Rogue Architects, LLC | B56: =Table1[[#This Row],[Column6]]+Table1[[#This Row],[Column5]]+Table1[[#This Row],[Column4]]+Table1[[#This Row],[Column3]]+Table1[[#This Row],[Column2]]+Table1[[#This Row],[Column1]]+2*(Table1[[#This Row],[Mkt Fit (1-3)]])+Table1[[#This Row],[Column7]]+Table1[[#This Row],[Column8]]+Table1[[#This Row],[Column9]] -> 14 | C56: Connection | D56: ⮽ | E56: ✓ | F56: ⮽ | G56: ⮽ | H56: ⮽ | I56: ⮽ | J56: =IF(Table1[[#This Row],[CIV]]="⮽",0,1)*1.5 -> 0 | K56: =IF(Table1[[#This Row],[ARC]]="⮽",0,1)*3 -> 3 | L56: =IF(Table1[[#This Row],[STR]]="⮽",0,1)*2 -> 0 | M56: =IF(Table1[[#This Row],[MP]]="⮽",0,1) -> 0 | N56: =IF(Table1[[#This Row],[ELE]]="⮽",0,1) -> 0 | O56: =IF(Table1[[#This Row],[FP]]="⮽",0,1) -> 0 | P56: 3 | Q56: S | R56: =IF(Table1[[#This Row],[Size (S, M, L)]]="S",2,IF(Table1[[#This Row],[Size (S, M, L)]]="L",1,4)) -> 2 | S56: CST | T56: =IF(Table1[[#This Row],[TZone]]="EST",4,IF(Table1[[#This Row],[TZone]]="CST",3,IF(Table1[[#This Row],[TZone]]="MST",2,1))) -> 3 | U56: No | V56: =IF(Table1[[#This Row],[Low-cost office?]]="Yes",-4,0) -> 0
A57: SGA Design Group | B57: =Table1[[#This Row],[Column6]]+Table1[[#This Row],[Column5]]+Table1[[#This Row],[Column4]]+Table1[[#This Row],[Column3]]+Table1[[#This Row],[Column2]]+Table1[[#This Row],[Column1]]+2*(Table1[[#This Row],[Mkt Fit (1-3)]])+Table1[[#This Row],[Column7]]+Table1[[#This Row],[Column8]]+Table1[[#This Row],[Column9]] -> 14 | C57: Client | D57: ⮽ | E57: ✓ | F57: ⮽ | G57: ⮽ | H57: ⮽ | I57: ⮽ | J57: =IF(Table1[[#This Row],[CIV]]="⮽",0,1)*1.5 -> 0 | K57: =IF(Table1[[#This Row],[ARC]]="⮽",0,1)*3 -> 3 | L57: =IF(Table1[[#This Row],[STR]]="⮽",0,1)*2 -> 0 | M57: =IF(Table1[[#This Row],[MP]]="⮽",0,1) -> 0 | N57: =IF(Table1[[#This Row],[ELE]]="⮽",0,1) -> 0 | O57: =IF(Table1[[#This Row],[FP]]="⮽",0,1) -> 0 | P57: 3 | Q57: S | R57: =IF(Table1[[#This Row],[Size (S, M, L)]]="S",2,IF(Table1[[#This Row],[Size (S, M, L)]]="L",1,4)) -> 2 | S57: CST | T57: =IF(Table1[[#This Row],[TZone]]="EST",4,IF(Table1[[#This Row],[TZone]]="CST",3,IF(Table1[[#This Row],[TZone]]="MST",2,1))) -> 3 | U57: No | V57: =IF(Table1[[#This Row],[Low-cost office?]]="Yes",-4,0) -> 0
A58: The McIntosh Group | B58: =Table1[[#This Row],[Column6]]+Table1[[#This Row],[Column5]]+Table1[[#This Row],[Column4]]+Table1[[#This Row],[Column3]]+Table1[[#This Row],[Column2]]+Table1[[#This Row],[Column1]]+2*(Table1[[#This Row],[Mkt Fit (1-3)]])+Table1[[#This Row],[Column7]]+Table1[[#This Row],[Column8]]+Table1[[#This Row],[Column9]] -> 14 | C58: Connection | D58: ⮽ | E58: ✓ | F58: ⮽ | G58: ⮽ | H58: ⮽ | I58: ⮽ | J58: =IF(Table1[[#This Row],[CIV]]="⮽",0,1)*1.5 -> 0 | K58: =IF(Table1[[#This Row],[ARC]]="⮽",0,1)*3 -> 3 | L58: =IF(Table1[[#This Row],[STR]]="⮽",0,1)*2 -> 0 | M58: =IF(Table1[[#This Row],[MP]]="⮽",0,1) -> 0 | N58: =IF(Table1[[#This Row],[ELE]]="⮽",0,1) -> 0 | O58: =IF(Table1[[#This Row],[FP]]="⮽",0,1) -> 0 | P58: 3 | Q58: S | R58: =IF(Table1[[#This Row],[Size (S, M, L)]]="S",2,IF(Table1[[#This Row],[Size (S, M, L)]]="L",1,4)) -> 2 | S58: CST | T58: =IF(Table1[[#This Row],[TZone]]="EST",4,IF(Table1[[#This Row],[TZone]]="CST",3,IF(Table1[[#This Row],[TZone]]="MST",2,1))) -> 3 | U58: No | V58: =IF(Table1[[#This Row],[Low-cost office?]]="Yes",-4,0) -> 0
... A170: Civil & Environmental Consultants | B170: =Table1[[#This Row],[Column6]]+Table1[[#This Row],[Column5]]+Table1[[#This Row],[Column4]]+Table1[[#This Row],[Column3]]+Table1[[#This Row],[Column2]]+Table1[[#This Row],[Column1]]+2*(Table1[[#This Row],[Mkt Fit (1-3)]])+Table1[[#This Row],[Column7]]+Table1[[#This Row],[Column8]]+Table1[[#This Row],[Column9]] -> 3.5 | C170: Target | D170: ✓ | E170: ⮽ | F170: ⮽ | G170: ⮽ | H170: ⮽ | I170: ⮽ | J170: =IF(Table1[[#This Row],[CIV]]="⮽",0,1)*1.5 -> 1.5 | K170: =IF(Table1[[#This Row],[ARC]]="⮽",0,1)*3 -> 0 | L170: =IF(Table1[[#This Row],[STR]]="⮽",0,1)*2 -> 0 | M170: =IF(Table1[[#This Row],[MP]]="⮽",0,1) -> 0 | N170: =IF(Table1[[#This Row],[ELE]]="⮽",0,1) -> 0 | O170: =IF(Table1[[#This Row],[FP]]="⮽",0,1) -> 0 | P170: 1 | Q170: L | R170: =IF(Table1[[#This Row],[Size (S, M, L)]]="S",2,IF(Table1[[#This Row],[Size (S, M, L)]]="L",1,4)) -> 1 | S170: CST | T170: =IF(Table1[[#This Row],[TZone]]="EST",4,IF(Table1[[#This Row],[TZone]]="CST",3,IF(Table1[[#This Row],[TZone]]="MST",2,1))) -> 3 | U170: Yes | V170: =IF(Table1[[#This Row],[Low-cost office?]]="Yes",-4,0) -> -4

Sheet Centerbuild 2025
A1: Company | B1: Score | C1: Status | D1: CIV | E1: ARC | F1: STR | G1: MP | H1: ELE | I1: FP | J1: Column6 | K1: Column5 | L1: Column4 | M1: Column3 | N1: Column2 | O1: Column1 | P1: Mkt Fit (1-3) | Q1: Size (S, M, L) | R1: Column7 | S1: TZone | T1: Column8 | U1: Low-cost office? | V1: Column9 | W1: Using Competitor? | X1: Attended in 2024
A2: HFA | B2: =Table1[[#This Row],[Column6]]+Table1[[#This Row],[Column5]]+Table1[[#This Row],[Column4]]+Table1[[#This Row],[Column3]]+Table1[[#This Row],[Column2]]+Table1[[#This Row],[Column1]]+2*(Table1[[#This Row],[Mkt Fit (1-3)]])+Table1[[#This Row],[Column7]]+Table1[[#This Row],[Column8]]+Table1[[#This Row],[Column9]] -> 23.5 | C2: Contact | D2: ✓ | E2: ✓ | F2: ✓ | G2: ✓ | H2: ✓ | I2: ✓ | J2: =IF(Table1[[#This Row],[CIV]]="⮽",0,1)*1.5 -> 1.5 | K2: =IF(Table1[[#This Row],[ARC]]="⮽",0,1)*3 -> 3 | L2: =IF(Table1[[#This Row],[STR]]="⮽",0,1)*2 -> 2 | M2: =IF(Table1[[#This Row],[MP]]="⮽",0,1) -> 1 | N2: =IF(Table1[[#This Row],[ELE]]="⮽",0,1) -> 1 | O2: =IF(Table1[[#This Row],[FP]]="⮽",0,1) -> 1 | P2: 3 | Q2: M | R2: =IF(Table1[[#This Row],[Size (S, M, L)]]="S",2,IF(Table1[[#This Row],[Size (S, M, L)]]="L",1,4)) -> 4 | S2: EST | T2: =IF(Table1[[#This Row],[TZone]]="EST",4,IF(Table1[[#This Row],[TZone]]="CST",3,IF(Table1[[#This Row],[TZone]]="MST",2,1))) -> 4 | U2: No | V2: =IF(Table1[[#This Row],[Low-cost office?]]="Yes",-4,0) -> 0 | X2: Yes
A3: Benchmark Group | B3: =Table1[[#This Row],[Column6]]+Table1[[#This Row],[Column5]]+Table1[[#This Row],[Column4]]+Table1[[#This Row],[Column3]]+Table1[[#This Row],[Column2]]+Table1[[#This Row],[Column1]]+2*(Table1[[#This Row],[Mkt Fit (1-3)]])+Table1[[#This Row],[Column7]]+Table1[[#This Row],[Column8]]+Table1[[#This Row],[Column9]] -> 23.5 | C3: Contact | D3: ✓ | E3: ✓ | F3: ✓ | G3: ✓ | H3: ✓ | I3: ✓ | J3: =IF(Table1[[#This Row],[CIV]]="⮽",0,1)*1.5 -> 1.5 | K3: =IF(Table1[[#This Row],[ARC]]="⮽",0,1)*3 -> 3 | L3: =IF(Table1[[#This Row],[STR]]="⮽",0,1)*2 -> 2 | M3: =IF(Table1[[#This Row],[MP]]="⮽",0,1) -> 1 | N3: =IF(Table1[[#This Row],[ELE]]="⮽",0,1) -> 1 | O3: =IF(Table1[[#This Row],[FP]]="⮽",0,1) -> 1 | P3: 3 | Q3: M | R3: =IF(Table1[[#This Row],[Size (S, M, L)]]="S",2,IF(Table1[[#This Row],[Size (S, M, L)]]="L",1,4)) -> 4 | S3: CST | T3: =IF(Table1[[#This Row],[TZone]]="EST",4,IF(Table1[[#This Row],[TZone]]="CST",3,IF(Table1[[#This Row],[TZone]]="MST",2,1))) -> 4 | U3: No | V3: =IF(Table1[[#This Row],[Low-cost office?]]="Yes",-4,0) -> 0 | X3: Yes
A4: Core States Group | B4: =Table1[[#This Row],[Column6]]+Table1[[#This Row],[Column5]]+Table1[[#This Row],[Column4]]+Table1[[#This Row],[Column3]]+Table1[[#This Row],[Column2]]+Table1[[#This Row],[Column1]]+2*(Table1[[#This Row],[Mkt Fit (1-3)]])+Table1[[#This Row],[Column7]]+Table1[[#This Row],[Column8]]+Table1[[#This Row],[Column9]] -> 22.5 | C4: Client | D4: ✓ | E4: ✓ | F4: ✓ | G4: ✓ | H4: ✓ | I4: ✓ | J4: =IF(Table1[[#This Row],[CIV]]="⮽",0,1)*1.5 -> 1.5 | K4: =IF(Table1[[#This Row],[ARC]]="⮽",0,1)*3 -> 3 | L4: =IF(Table1[[#This Row],[STR]]="⮽",0,1)*2 -> 2 | M4: =IF(Table1[[#This Row],[MP]]="⮽",0,1) -> 1 | N4: =IF(Table1[[#This Row],[ELE]]="⮽",0,1) -> 1 | O4: =IF(Table1[[#This Row],[FP]]="⮽",0,1) -> 1 | P4: 3 | Q4: M | R4: =IF(Table1[[#This Row],[Size (S, M, L)]]="S",2,IF(Table1[[#This Row],[Size (S, M, L)]]="L",1,4)) -> 4 | S4: CST | T4: =IF(Table1[[#This Row],[TZone]]="EST",4,IF(Table1[[#This Row],[TZone]]="CST",3,IF(Table1[[#This Row],[TZone]]="MST",2,1))) -> 3 | U4: No | V4: =IF(Table1[[#This Row],[Low-cost office?]]="Yes",-4,0) -> 0 | X4: Yes
A5: GreenbergFarrow | B5: =Table1[[#This Row],[Column6]]+Table1[[#This Row],[Column5]]+Table1[[#This Row],[Column4]]+Table1[[#This Row],[Column3]]+Table1[[#This Row],[Column2]]+Table1[[#This Row],[Column1]]+2*(Table1[[#This Row],[Mkt Fit (1-3)]])+Table1[[#This Row],[Column7]]+Table1[[#This Row],[Column8]]+Table1[[#This Row],[Column9]] -> 22.5 | C5: Target | D5: ✓ | E5: ✓ | F5: ✓ | G5: ✓ | H5: ✓ | I5: ⮽ | J5: =IF(Table1[[#This Row],[CIV]]="⮽",0,1)*1.5 -> 1.5 | K5: =IF(Table1[[#This Row],[ARC]]="⮽",0,1)*3 -> 3 | L5: =IF(Table1[[#This Row],[STR]]="⮽",0,1)*2 -> 2 | M5: =IF(Table1[[#This Row],[MP]]="⮽",0,1) -> 1 | N5: =IF(Table1[[#This Row],[ELE]]="⮽",0,1) -> 1 | O5: =IF(Table1[[#This Row],[FP]]="⮽",0,1) -> 1 | P5: 3 | Q5: M | R5: =IF(Table1[[#This Row],[Size (S, M, L)]]="S",2,IF(Table1[[#This Row],[Size (S, M, L)]]="L",1,4)) -> 4 | S5: EST | T5: =IF(Table1[[#This Row],[TZone]]="EST",4,IF(Table1[[#This Row],[TZone]]="CST",3,IF(Table1[[#This Row],[TZone]]="MST",2,1))) -> 3 | U5: No | V5: =IF(Table1[[#This Row],[Low-cost office?]]="Yes",-4,0) -> 0 | X5: Yes
A6: CASCO | B6: =Table1[[#This Row],[Column6]]+Table1[[#This Row],[Column5]]+Table1[[#This Row],[Column4]]+Table1[[#This Row],[Column3]]+Table1[[#This Row],[Column2]]+Table1[[#This Row],[Column1]]+2*(Table1[[#This Row],[Mkt Fit (1-3)]])+Table1[[#This Row],[Column7]]+Table1[[#This Row],[Column8]]+Table1[[#This Row],[Column9]] -> 22.5 | C6: Target | D6: ✓ | E6: ✓ | F6: ✓ | G6: ✓ | H6: ✓ | I6: ✓ | J6: =IF(Table1[[#This Row],[CIV]]="⮽",0,1)*1.5 -> 1.5 | K6: =IF(Table1[[#This Row],[ARC]]="⮽",0,1)*3 -> 3 | L6: =IF(Table1[[#This Row],[STR]]="⮽",0,1)*2 -> 2 | M6: =IF(Table1[[#This Row],[MP]]="⮽",0,1) -> 1 | N6: =IF(Table1[[#This Row],[ELE]]="⮽",0,1) -> 1 | O6: =IF(Table1[[#This Row],[FP]]="⮽",0,1) -> 0 | P6: 3 | Q6: M | R6: =IF(Table1[[#This Row],[Size (S, M, L)]]="S",2,IF(Table1[[#This Row],[Size (S, M, L)]]="L",1,4)) -> 4 | S6: CST | T6: =IF(Table1[[#This Row],[TZone]]="EST",4,IF(Table1[[#This Row],[TZone]]="CST",3,IF(Table1[[#This Row],[TZone]]="MST",2,1))) -> 4 | U6: No | V6: =IF(Table1[[#This Row],[Low-cost office?]]="Yes",-4,0) -> 0 | X6: No
A7: The Dimension Group | B7: =Table1[[#This Row],[Column6]]+Table1[[#This Row],[Column5]]+Table1[[#This Row],[Column4]]+Table1[[#This Row],[Column3]]+Table1[[#This Row],[Column2]]+Table1[[#This Row],[Column1]]+2*(Table1[[#This Row],[Mkt Fit (1-3)]])+Table1[[#This Row],[Column7]]+Table1[[#This Row],[Column8]]+Table1[[#This Row],[Column9]] -> 21.5 | C7: Target | D7: ✓ | E7: ✓ | F7: ✓ | G7: ✓ | H7: ✓ | I7: ✓ | J7: =IF(Table1[[#This Row],[CIV]]="⮽",0,1)*1.5 -> 1.5 | K7: =IF(Table1[[#This Row],[ARC]]="⮽",0,1)*3 -> 3 | L7: =IF(Table1[[#This Row],[STR]]="⮽",0,1)*2 -> 2 | M7: =IF(Table1[[#This Row],[MP]]="⮽",0,1) -> 1 | N7: =IF(Table1[[#This Row],[ELE]]="⮽",0,1) -> 1 | O7: =IF(Table1[[#This Row],[FP]]="⮽",0,1) -> 1 | P7: 3 | Q7: M | R7: =IF(Table1[[#This Row],[Size (S, M, L)]]="S",2,IF(Table1[[#This Row],[Size (S, M, L)]]="L",1,4)) -> 4 | S7: CST | T7: =IF(Table1[[#This Row],[TZone]]="EST",4,IF(Table1[[#This Row],[TZone]]="CST",3,IF(Table1[[#This Row],[TZone]]="MST",2,1))) -> 4 | U7: No | V7: =IF(Table1[[#This Row],[Low-cost office?]]="Yes",-4,0) -> 0 | X7: No
A8: Sargenti Architects | B8: =Table1[[#This Row],[Column6]]+Table1[[#This Row],[Column5]]+Table1[[#This Row],[Column4]]+Table1[[#This Row],[Column3]]+Table1[[#This Row],[Column2]]+Table1[[#This Row],[Column1]]+2*(Table1[[#This Row],[Mkt Fit (1-3)]])+Table1[[#This Row],[Column7]]+Table1[[#This Row],[Column8]]+Table1[[#This Row],[Column9]] -> 21.5 | C8: Target | D8: ⮽ | E8: ✓ | F8: ✓ | G8: ✓ | H8: ✓ | I8: ✓ | J8: =IF(Table1[[#This Row],[CIV]]="⮽",0,1)*1.5 -> 1.5 | K8: =IF(Table1[[#This Row],[ARC]]="⮽",0,1)*3 -> 3 | L8: =IF(Table1[[#This Row],[STR]]="⮽",0,1)*2 -> 2 | M8: =IF(Table1[[#This Row],[MP]]="⮽",0,1) -> 1 | N8: =IF(Table1[[#This Row],[ELE]]="⮽",0,1) -> 1 | O8: =IF(Table1[[#This Row],[FP]]="⮽",0,1) -> 0 | P8: 3 | Q8: M | R8: =IF(Table1[[#This Row],[Size (S, M, L)]]="S",2,IF(Table1[[#This Row],[Size (S, M, L)]]="L",1,4)) -> 4 | S8: EST | T8: =IF(Table1[[#This Row],[TZone]]="EST",4,IF(Table1[[#This Row],[TZone]]="CST",3,IF(Table1[[#This Row],[TZone]]="MST",2,1))) -> 3 | U8: No | V8: =IF(Table1[[#This Row],[Low-cost office?]]="Yes",-4,0) -> 0 | X8: No
A9: BL Companies | B9: =Table1[[#This Row],[Column6]]+Table1[[#This Row],[Column5]]+Table1[[#This Row],[Column4]]+Table1[[#This Row],[Column3]]+Table1[[#This Row],[Column2]]+Table1[[#This Row],[Column1]]+2*(Table1[[#This Row],[Mkt Fit (1-3)]])+Table1[[#This Row],[Column7]]+Table1[[#This Row],[Column8]]+Table1[[#This Row],[Column9]] -> 21.5 | C9: Contact | D9: ✓ | E9: ✓ | F9: ✓ | G9: ✓ | H9: ✓ | I9: ✓ | J9: =IF(Table1[[#This Row],[CIV]]="⮽",0,1)*1.5 -> 1.5 | K9: =IF(Table1[[#This Row],[ARC]]="⮽",0,1)*3 -> 3 | L9: =IF(Table1[[#This Row],[STR]]="⮽",0,1)*2 -> 2 | M9: =IF(Table1[[#This Row],[MP]]="⮽",0,1) -> 1 | N9: =IF(Table1[[#This Row],[ELE]]="⮽",0,1) -> 1 | O9: =IF(Table1[[#This Row],[FP]]="⮽",0,1) -> 1 | P9: 2 | Q9: M | R9: =IF(Table1[[#This Row],[Size (S, M, L)]]="S",2,IF(Table1[[#This Row],[Size (S, M, L)]]="L",1,4)) -> 4 | S9: EST | T9: =IF(Table1[[#This Row],[TZone]]="EST",4,IF(Table1[[#This Row],[TZone]]="CST",3,IF(Table1[[#This Row],[TZone]]="MST",2,1))) -> 4 | U9: No | V9: =IF(Table1[[#This Row],[Low-cost office?]]="Yes",-4,0) -> 0 | X9: Yes
A10: CESO, Inc. | B10: =Table1[[#This Row],[Column6]]+Table1[[#This Row],[Column5]]+Table1[[#This Row],[Column4]]+Table1[[#This Row],[Column3]]+Table1[[#This Row],[Column2]]+Table1[[#This Row],[Column1]]+2*(Table1[[#This Row],[Mkt Fit (1-3)]])+Table1[[#This Row],[Column7]]+Table1[[#This Row],[Column8]]+Table1[[#This Row],[Column9]] -> 21 | C10: Client | D10: ✓ | E10: ✓ | F10: ✓ | G10: ✓ | H10: ✓ | I10: ⮽ | J10: =IF(Table1[[#This Row],[CIV]]="⮽",0,1)*1.5 -> 0 | K10: =IF(Table1[[#This Row],[ARC]]="⮽",0,1)*3 -> 3 | L10: =IF(Table1[[#This Row],[STR]]="⮽",0,1)*2 -> 2 | M10: =IF(Table1[[#This Row],[MP]]="⮽",0,1) -> 1 | N10: =IF(Table1[[#This Row],[ELE]]="⮽",0,1) -> 1 | O10: =IF(Table1[[#This Row],[FP]]="⮽",0,1) -> 0 | P10: 3 | Q10: M | R10: =IF(Table1[[#This Row],[Size (S, M, L)]]="S",2,IF(Table1[[#This Row],[Size (S, M, L)]]="L",1,4)) -> 4 | S10: CST | T10: =IF(Table1[[#This Row],[TZone]]="EST",4,IF(Table1[[#This Row],[TZone]]="CST",3,IF(Table1[[#This Row],[TZone]]="MST",2,1))) -> 4 | U10: No | V10: =IF(Table1[[#This Row],[Low-cost office?]]="Yes",-4,0) -> 0 | X10: Yes
A11: H2M Architects + Engineers | B11: =Table1[[#This Row],[Column6]]+Table1[[#This Row],[Column5]]+Table1[[#This Row],[Column4]]+Table1[[#This Row],[Column3]]+Table1[[#This Row],[Column2]]+Table1[[#This Row],[Column1]]+2*(Table1[[#This Row],[Mkt Fit (1-3)]])+Table1[[#This Row],[Column7]]+Table1[[#This Row],[Column8]]+Table1[[#This Row],[Column9]] -> 20.5 | C11: Target | D11: ✓ | E11: ✓ | F11: ✓ | G11: ✓ | H11: ✓ | I11: ✓ | J11: =IF(Table1[[#This Row],[CIV]]="⮽",0,1)*1.5 -> 1.5 | K11: =IF(Table1[[#This Row],[ARC]]="⮽",0,1)*3 -> 3 | L11: =IF(Table1[[#This Row],[STR]]="⮽",0,1)*2 -> 2 | M11: =IF(Table1[[#This Row],[MP]]="⮽",0,1) -> 1 | N11: =IF(Table1[[#This Row],[ELE]]="⮽",0,1) -> 1 | O11: =IF(Table1[[#This Row],[FP]]="⮽",0,1) -> 1 | P11: 2 | Q11: M | R11: =IF(Table1[[#This Row],[Size (S, M, L)]]="S",2,IF(Table1[[#This Row],[Size (S, M, L)]]="L",1,4)) -> 2 | S11: EST | T11: =IF(Table1[[#This Row],[TZone]]="EST",4,IF(Table1[[#This Row],[TZone]]="CST",3,IF(Table1[[#This Row],[TZone]]="MST",2,1))) -> 3 | U11: No | V11: =IF(Table1[[#This Row],[Low-cost office?]]="Yes",-4,0) -> 0 | X11: Yes
A12: Little | B12: =Table1[[#This Row],[Column6]]+Table1[[#This Row],[Column5]]+Table1[[#This Row],[Column4]]+Table1[[#This Row],[Column3]]+Table1[[#This Row],[Column2]]+Table1[[#This Row],[Column1]]+2*(Table1[[#This Row],[Mkt Fit (1-3)]])+Table1[[#This Row],[Column7]]+Table1[[#This Row],[Column8]]+Table1[[#This Row],[Column9]] -> 20.5 | C12: Contact | D12: ⮽ | E12: ✓ | F12: ✓ | G12: ✓ | H12: ✓ | I12: ⮽ | J12: =IF(Table1[[#This Row],[CIV]]="⮽",0,1)*1.5 -> 1.5 | K12: =IF(Table1[[#This Row],[ARC]]="⮽",0,1)*3 -> 3 | L12: =IF(Table1[[#This Row],[STR]]="⮽",0,1)*2 -> 2 | M12: =IF(Table1[[#This Row],[MP]]="⮽",0,1) -> 1 | N12: =IF(Table1[[#This Row],[ELE]]="⮽",0,1) -> 1 | O12: =IF(Table1[[#This Row],[FP]]="⮽",0,1) -> 0 | P12: 3 | Q12: M | R12: =IF(Table1[[#This Row],[Size (S, M, L)]]="S",2,IF(Table1[[#This Row],[Size (S, M, L)]]="L",1,4)) -> 4 | S12: EST | T12: =IF(Table1[[#This Row],[TZone]]="EST",4,IF(Table1[[#This Row],[TZone]]="CST",3,IF(Table1[[#This Row],[TZone]]="MST",2,1))) -> 2 | U12: No | V12: =IF(Table1[[#This Row],[Low-cost office?]]="Yes",-4,0) -> 0 | X12: Yes
